Workbook

Sheet Dashboard
A1: MUDANZAS METEPEC — DASHBOARD OPERATIVO
A2: ="Actualizado: "&TEXT(TODAY(),"DD/MM/YYYY")
B4: SERVICIOS
B5: Servicios HOY | D5: Esta SEMANA | F5: Este MES | H5: PENDIENTES | J5: CONFIRMADOS | L5: TERMINADOS mes
B6: =COUNTIF(Agenda!C:C,TODAY()) | D6: =COUNTIFS(Agenda!C:C,">="&TODAY()-WEEKDAY(TODAY(),2)+1,Agenda!C:C,"<="&TODAY()-WEEKDAY(TODAY(),2)+7) | F6: =COUNTIFS(Agenda!C:C,">="&DATE(YEAR(TODAY()),MONTH(TODAY()),1),Agenda!C:C,"<="&EOMONTH(TODAY(),0)) | H6: =COUNTIF(Agenda!Q:Q,"Pendiente") | J6: =COUNTIF(Agenda!Q:Q,"Confirmado") | L6: =COUNTIFS(Agenda!Q:Q,"Terminado",Agenda!C:C,">="&DATE(YEAR(TODAY()),MONTH(TODAY()),1))
B8: FINANZAS DEL MES
B9: VENTAS MES | D9: COSTOS MES | F9: UTILIDAD MES | H9: GASTOS FIJOS | J9: FLUJO NETO | L9: MARGEN PROM %
B10: =IFERROR(SUMIFS(Agenda!N:N,Agenda!C:C,">="&DATE(YEAR(TODAY()),MONTH(TODAY()),1),Agenda!C:C,"<="&EOMONTH(TODAY(),0)),0) | D10: =IFERROR(SUMIFS(Costos!P:P,Costos!P:P,">"&0),0) | F10: =IFERROR(SUMIFS(Agenda!N:N,Agenda!C:C,">="&DATE(YEAR(TODAY()),MONTH(TODAY()),1),Agenda!C:C,"<="&EOMONTH(TODAY(),0))-SUMIF(Costos!P:P,">"&0,Costos!P:P),0) | H10: =IFERROR('Gastos Fijos'!B11,0) | J10: =IFERROR(SUM(Flujo!C4:C504)-SUM(Flujo!D4:D504),0) | L10: =IFERROR(AVERAGE(Costos!S4:S203),0)
B12: VENTAS POR UNIDAD — MES ACTUAL
B13: UNIDAD | C13: SERVICIOS | D13: VENTAS $ | E13: META MES $ | F13: CUMP % | G13: FALTA $ | H13: UTILIDAD $
B14: Pick Up | C14: =COUNTIFS(Agenda!K:K,"Pick Up",Agenda!C:C,">="&DATE(YEAR(TODAY()),MONTH(TODAY()),1),Agenda!C:C,"<="&EOMONTH(TODAY(),0)) | D14: =SUMIFS(Agenda!N:N,Agenda!K:K,"Pick Up",Agenda!C:C,">="&DATE(YEAR(TODAY()),MONTH(TODAY()),1),Agenda!C:C,"<="&EOMONTH(TODAY(),0)) | E14: 24250 | F14: =IF(E14>0,D14/E14*100,0) | G14: =MAX(0,E14-D14) | H14: =SUMIF(Costos!C:C,"Pick Up",Costos!R:R)
B15: 1.5 Cerrada | C15: =COUNTIFS(Agenda!K:K,"1.5 Cerrada",Agenda!C:C,">="&DATE(YEAR(TODAY()),MONTH(TODAY()),1),Agenda!C:C,"<="&EOMONTH(TODAY(),0)) | D15: =SUMIFS(Agenda!N:N,Agenda!K:K,"1.5 Cerrada",Agenda!C:C,">="&DATE(YEAR(TODAY()),MONTH(TODAY()),1),Agenda!C:C,"<="&EOMONTH(TODAY(),0)) | E15: 28450 | F15: =IF(E15>0,D15/E15*100,0) | G15: =MAX(0,E15-D15) | H15: =SUMIF(Costos!C:C,"1.5 Cerrada",Costos!R:R)
B16: 2.5 | C16: =COUNTIFS(Agenda!K:K,"2.5",Agenda!C:C,">="&DATE(YEAR(TODAY()),MONTH(TODAY()),1),Agenda!C:C,"<="&EOMONTH(TODAY(),0)) | D16: =SUMIFS(Agenda!N:N,Agenda!K:K,"2.5",Agenda!C:C,">="&DATE(YEAR(TODAY()),MONTH(TODAY()),1),Agenda!C:C,"<="&EOMONTH(TODAY(),0)) | E16: 31250 | F16: =IF(E16>0,D16/E16*100,0) | G16: =MAX(0,E16-D16) | H16: =SUMIF(Costos!C:C,"2.5",Costos!R:R)
B17: 3.5 | C17: =COUNTIFS(Agenda!K:K,"3.5",Agenda!C:C,">="&DATE(YEAR(TODAY()),MONTH(TODAY()),1),Agenda!C:C,"<="&EOMONTH(TODAY(),0)) | D17: =SUMIFS(Agenda!N:N,Agenda!K:K,"3.5",Agenda!C:C,">="&DATE(YEAR(TODAY()),MONTH(TODAY()),1),Agenda!C:C,"<="&EOMONTH(TODAY(),0)) | E17: 15250 | F17: =IF(E17>0,D17/E17*100,0) | G17: =MAX(0,E17-D17) | H17: =SUMIF(Costos!C:C,"3.5",Costos!R:R)
B19: CRM — CONVERSIÓN DE CLIENTES
B20: CONTACTOS | D20: COTIZACIONES | F20: CERRADOS | H20: TASA CIERRE | J20: RESEÑAS | L20: RECURRENTES
B21: =COUNTA(Clientes!A4:A303) | D21: =COUNTA(Clientes!F4:F303) | F21: =COUNTIF(Clientes!G4:G303,"Sí") | H21: =IF(COUNTA(Clientes!A4:A303)>0,COUNTIF(Clientes!G4:G303,"Sí")/COUNTA(Clientes!A4:A303)*100,0) | J21: =COUNTIF(Clientes!K4:K303,"Sí") | L21: =COUNTIF(Clientes!L4:L303,"Sí")
B23: COBERTURA GASTOS FIJOS | H23: MEJOR UNIDAD DEL MES
B24: ="Ventas: $"&TEXT(IFERROR(SUM(Agenda!N:N),0),"#,##0")&" / Meta: $"&TEXT(IFERROR('Gastos Fijos'!B11,0),"#,##0")&" ("&TEXT(IFERROR(SUM(Agenda!N:N)/'Gastos Fijos'!B11*100,0),"0.0")&"%)" | H24: =IFERROR(INDEX({"Pick Up","1.5 Cerrada","2.5","3.5"},MATCH(MAX(SUMIF(Agenda!K:K,"Pick Up",Agenda!N:N),SUMIF(Agenda!K:K,"1.5 Cerrada",Agenda!N:N),SUMIF(Agenda!K:K,"2.5",Agenda!N:N),SUMIF(Agenda!K:K,"3.5",Agenda!N:N)),{SUMIF(Agenda!K:K,"Pick Up",Agenda!N:N),SUMIF(Agenda!K:K,"1.5 Cerrada",Agenda!N:N),SUMIF(Agenda!K:K,"2.5",Agenda!N:N),SUMIF(Agenda!K:K,"3.5",Agenda!N:N)},0)),"—")
B27: OPERACIÓN Y RENTABILIDAD
B28: CANCELADOS mes | D28: EN PROCESO | F28: COSTO PROM./SV | H28: INGRESO PROM./SV | J28: COSTO MTO TOTAL | L28: UNIDAD MÁS OCUP.
B29: =COUNTIFS(Agenda!Q:Q,"Cancelado",Agenda!C:C,">="&DATE(YEAR(TODAY()),MONTH(TODAY()),1)) | D29: =COUNTIF(Agenda!Q:Q,"En proceso") | F29: =IFERROR(SUM(Costos!P4:P203)/COUNTA(Costos!A4:A203),0) | H29: =IFERROR(SUM(Agenda!N4:N203)/COUNTA(Agenda!E4:E203),0) | J29: =IFERROR(SUM(Mantenimiento!F4:F303),0) | L29: =IFERROR(INDEX({"Pick Up","1.5 Cerrada","2.5","3.5"},MATCH(MAX(COUNTIFS(Agenda!K:K,"Pick Up",Agenda!Q:Q,"Terminado"),COUNTIFS(Agenda!K:K,"1.5 Cerrada",Agenda!Q:Q,"Terminado"),COUNTIFS(Agenda!K:K,"2.5",Agenda!Q:Q,"Terminado"),COUNTIFS(Agenda!K:K,"3.5",Agenda!Q:Q,"Terminado")),{COUNTIFS(Agenda!K:K,"Pick Up",Agenda!Q:Q,"Terminado"),COUNTIFS(Agenda!K:K,"1.5 Cerrada",Agenda!Q:Q,"Terminado"),COUNTIFS(Agenda!K:K,"2.5",Agenda!Q:Q,"Terminado"),COUNTIFS(Agenda!K:K,"3.5",Agenda!Q:Q,"Terminado")},0)),"—")
B31: UTILIDAD Y RENTABILIDAD POR UNIDAD (ACUMULADO)
B32: UNIDAD | C32: VENTAS $ | D32: COSTOS $ | E32: UTILIDAD $ | F32: MARGEN % | G32: COSTO MTO $ | H32: UTIL.NETA $
B33: Pick Up | C33: =SUMIF(Agenda!K:K,"Pick Up",Agenda!N:N) | D33: =SUMIF(Costos!C:C,"Pick Up",Costos!P:P) | E33: =C33-D33 | F33: =IF(C33>0,E33/C33*100,0) | G33: =SUMIF(Mantenimiento!C:C,"Pick Up",Mantenimiento!F:F) | H33: =E33-G33
B34: 1.5 Cerrada | C34: =SUMIF(Agenda!K:K,"1.5 Cerrada",Agenda!N:N) | D34: =SUMIF(Costos!C:C,"1.5 Cerrada",Costos!P:P) | E34: =C34-D34 | F34: =IF(C34>0,E34/C34*100,0) | G34: =SUMIF(Mantenimiento!C:C,"1.5 Cerrada",Mantenimiento!F:F) | H34: =E34-G34
B35: 2.5 | C35: =SUMIF(Agenda!K:K,"2.5",Agenda!N:N) | D35: =SUMIF(Costos!C:C,"2.5",Costos!P:P) | E35: =C35-D35 | F35: =IF(C35>0,E35/C35*100,0) | G35: =SUMIF(Mantenimiento!C:C,"2.5",Mantenimiento!F:F) | H35: =E35-G35
B36: 3.5 | C36: =SUMIF(Agenda!K:K,"3.5",Agenda!N:N) | D36: =SUMIF(Costos!C:C,"3.5",Costos!P:P) | E36: =C36-D36 | F36: =IF(C36>0,E36/C36*100,0) | G36: =SUMIF(Mantenimiento!C:C,"3.5",Mantenimiento!F:F) | H36: =E36-G36

Sheet Agenda
A1: MUDANZAS METEPEC — AGENDA DE SERVICIOS
A2: Registro de todos los servicios: WhatsApp → Cobro → Análisis
A3: FOLIO | B3: F.REGISTRO | C3: F.SERVICIO | D3: HORA | E3: CLIENTE | F3: TELÉFONO | G3: TIPO | H3: ORIGEN | I3: DESTINO | J3: KM BASE | K3: UNIDAD | L3: PERSONAL | M3: DESCRIPCIÓN | N3: COTIZADO | O3: ANTICIPO | P3: SALDO | Q3: ESTADO | R3: PAGO | S3: FACTURA | T3: CANT.PERSONAS | U3: FOLIO COSTO | V3: OBSERVACIONES | W3: PRIORIDAD | X3: HORA SALIDA | Y3: HORA LLEGADA | Z3: HORA TÉRMINO | AA3: T.ESTIMADO hrs | AB3: T.REAL hrs | AC3: FOTOS | AD3: VIDEOS | AE3: RESEÑA SOL. | AF3: RESEÑA REC. | AG3: PERM.PUBLICAR | AH3: FUENTE | AI3: TIPO CLIENTE | AJ3: OBS.CLIENTE | AK3: CANCELACIÓN
A4: =IF(E4<>"","MUD-"&TEXT(ROW()-3,"000"),"") | B4: =IF(E4<>"",TODAY(),"") | P4: =IF(N4<>"",N4-O4,"") | U4: =IF(E4<>"","MUD-"&TEXT(ROW()-3,"000"),"") | AB4: =IF(AND(X4<>"",Z4<>""),IFERROR((Z4-X4)*24,""),"")
A5: =IF(E5<>"","MUD-"&TEXT(ROW()-3,"000"),"") | B5: =IF(E5<>"",TODAY(),"") | P5: =IF(N5<>"",N5-O5,"") | U5: =IF(E5<>"","MUD-"&TEXT(ROW()-3,"000"),"") | AB5: =IF(AND(X5<>"",Z5<>""),IFERROR((Z5-X5)*24,""),"")
A6: =IF(E6<>"","MUD-"&TEXT(ROW()-3,"000"),"") | B6: =IF(E6<>"",TODAY(),"") | P6: =IF(N6<>"",N6-O6,"") | U6: =IF(E6<>"","MUD-"&TEXT(ROW()-3,"000"),"") | AB6: =IF(AND(X6<>"",Z6<>""),IFERROR((Z6-X6)*24,""),"")
A7: =IF(E7<>"","MUD-"&TEXT(ROW()-3,"000"),"") | B7: =IF(E7<>"",TODAY(),"") | P7: =IF(N7<>"",N7-O7,"") | U7: =IF(E7<>"","MUD-"&TEXT(ROW()-3,"000"),"") | AB7: =IF(AND(X7<>"",Z7<>""),IFERROR((Z7-X7)*24,""),"")
A8: =IF(E8<>"","MUD-"&TEXT(ROW()-3,"000"),"") | B8: =IF(E8<>"",TODAY(),"") | P8: =IF(N8<>"",N8-O8,"") | U8: =IF(E8<>"","MUD-"&TEXT(ROW()-3,"000"),"") | AB8: =IF(AND(X8<>"",Z8<>""),IFERROR((Z8-X8)*24,""),"")
A9: =IF(E9<>"","MUD-"&TEXT(ROW()-3,"000"),"") | B9: =IF(E9<>"",TODAY(),"") | P9: =IF(N9<>"",N9-O9,"") | U9: =IF(E9<>"","MUD-"&TEXT(ROW()-3,"000"),"") | AB9: =IF(AND(X9<>"",Z9<>""),IFERROR((Z9-X9)*24,""),"")
A10: =IF(E10<>"","MUD-"&TEXT(ROW()-3,"000"),"") | B10: =IF(E10<>"",TODAY(),"") | P10: =IF(N10<>"",N10-O10,"") | U10: =IF(E10<>"","MUD-"&TEXT(ROW()-3,"000"),"") | AB10: =IF(AND(X10<>"",Z10<>""),IFERROR((Z10-X10)*24,""),"")
A11: =IF(E11<>"","MUD-"&TEXT(ROW()-3,"000"),"") | B11: =IF(E11<>"",TODAY(),"") | P11: =IF(N11<>"",N11-O11,"") | U11: =IF(E11<>"","MUD-"&TEXT(ROW()-3,"000"),"") | AB11: =IF(AND(X11<>"",Z11<>""),IFERROR((Z11-X11)*24,""),"")
A12: =IF(E12<>"","MUD-"&TEXT(ROW()-3,"000"),"") | B12: =IF(E12<>"",TODAY(),"") | P12: =IF(N12<>"",N12-O12,"") | U12: =IF(E12<>"","MUD-"&TEXT(ROW()-3,"000"),"") | AB12: =IF(AND(X12<>"",Z12<>""),IFERROR((Z12-X12)*24,""),"")
A13: =IF(E13<>"","MUD-"&TEXT(ROW()-3,"000"),"") | B13: =IF(E13<>"",TODAY(),"") | P13: =IF(N13<>"",N13-O13,"") | U13: =IF(E13<>"","MUD-"&TEXT(ROW()-3,"000"),"") | AB13: =IF(AND(X13<>"",Z13<>""),IFERROR((Z13-X13)*24,""),"")
A14: =IF(E14<>"","MUD-"&TEXT(ROW()-3,"000"),"") | B14: =IF(E14<>"",TODAY(),"") | P14: =IF(N14<>"",N14-O14,"") | U14: =IF(E14<>"","MUD-"&TEXT(ROW()-3,"000"),"") | AB14: =IF(AND(X14<>"",Z14<>""),IFERROR((Z14-X14)*24,""),"")
A15: =IF(E15<>"","MUD-"&TEXT(ROW()-3,"000"),"") | B15: =IF(E15<>"",TODAY(),"") | P15: =IF(N15<>"",N15-O15,"") | U15: =IF(E15<>"","MUD-"&TEXT(ROW()-3,"000"),"") | AB15: =IF(AND(X15<>"",Z15<>""),IFERROR((Z15-X15)*24,""),"")
... A203: =IF(E203<>"","MUD-"&TEXT(ROW()-3,"000"),"") | B203: =IF(E203<>"",TODAY(),"") | P203: =IF(N203<>"",N203-O203,"") | U203: =IF(E203<>"","MUD-"&TEXT(ROW()-3,"000"),"") | AB203: =IF(AND(X203<>"",Z203<>""),IFERROR((Z203-X203)*24,""),"")

Sheet Costos
A1: MUDANZAS METEPEC — COSTOS DEL SERVICIO
A2: Conectado por Folio con Agenda | Costo $7/km Pick Up · $9/km 1.5C · $10/km 2.5 · $12/km 3.5
A3: FOLIO | B3: CLIENTE | C3: UNIDAD | D3: KM REALES | E3: $/KM | F3: COSTO UNIDAD | G3: CHOFER | H3: AYUDANTES | I3: MANIOBRAS | J3: CASETAS | K3: COMIDAS | L3: HOTELES | M3: GASOLINA+ | N3: MATERIALES | O3: OTROS | P3: TOTAL GASTOS | Q3: PRECIO COBRADO | R3: UTILIDAD | S3: MARGEN % | T3: NOTAS
B4: =IF(A4<>"",IFERROR(VLOOKUP(A4,Agenda!A:E,5,0),"—"),"") | C4: =IF(A4<>"",IFERROR(VLOOKUP(A4,Agenda!A:K,11,0),"—"),"") | E4: =IF(A4<>"",IF(C4="Pick Up",7,IF(C4="1.5 Cerrada",9,IF(C4="2.5",10,IF(C4="3.5",12,0)))),"") | F4: =IF(AND(D4<>"",E4<>""),D4*E4,"") | P4: =IF(A4<>"",IFERROR(F4+G4+H4+I4+J4+K4+L4+M4+N4+O4,0),"") | Q4: =IF(A4<>"",IFERROR(VLOOKUP(A4,Agenda!A:N,14,0),0),"") | R4: =IF(A4<>"",Q4-P4,"") | S4: =IF(AND(A4<>"",Q4<>0),R4/Q4*100,"")
B5: =IF(A5<>"",IFERROR(VLOOKUP(A5,Agenda!A:E,5,0),"—"),"") | C5: =IF(A5<>"",IFERROR(VLOOKUP(A5,Agenda!A:K,11,0),"—"),"") | E5: =IF(A5<>"",IF(C5="Pick Up",7,IF(C5="1.5 Cerrada",9,IF(C5="2.5",10,IF(C5="3.5",12,0)))),"") | F5: =IF(AND(D5<>"",E5<>""),D5*E5,"") | P5: =IF(A5<>"",IFERROR(F5+G5+H5+I5+J5+K5+L5+M5+N5+O5,0),"") | Q5: =IF(A5<>"",IFERROR(VLOOKUP(A5,Agenda!A:N,14,0),0),"") | R5: =IF(A5<>"",Q5-P5,"") | S5: =IF(AND(A5<>"",Q5<>0),R5/Q5*100,"") | V5: Tabla $/km
B6: =IF(A6<>"",IFERROR(VLOOKUP(A6,Agenda!A:E,5,0),"—"),"") | C6: =IF(A6<>"",IFERROR(VLOOKUP(A6,Agenda!A:K,11,0),"—"),"") | E6: =IF(A6<>"",IF(C6="Pick Up",7,IF(C6="1.5 Cerrada",9,IF(C6="2.5",10,IF(C6="3.5",12,0)))),"") | F6: =IF(AND(D6<>"",E6<>""),D6*E6,"") | P6: =IF(A6<>"",IFERROR(F6+G6+H6+I6+J6+K6+L6+M6+N6+O6,0),"") | Q6: =IF(A6<>"",IFERROR(VLOOKUP(A6,Agenda!A:N,14,0),0),"") | R6: =IF(A6<>"",Q6-P6,"") | S6: =IF(AND(A6<>"",Q6<>0),R6/Q6*100,"") | V6: Pick Up | W6: 7
B7: =IF(A7<>"",IFERROR(VLOOKUP(A7,Agenda!A:E,5,0),"—"),"") | C7: =IF(A7<>"",IFERROR(VLOOKUP(A7,Agenda!A:K,11,0),"—"),"") | E7: =IF(A7<>"",IF(C7="Pick Up",7,IF(C7="1.5 Cerrada",9,IF(C7="2.5",10,IF(C7="3.5",12,0)))),"") | F7: =IF(AND(D7<>"",E7<>""),D7*E7,"") | P7: =IF(A7<>"",IFERROR(F7+G7+H7+I7+J7+K7+L7+M7+N7+O7,0),"") | Q7: =IF(A7<>"",IFERROR(VLOOKUP(A7,Agenda!A:N,14,0),0),"") | R7: =IF(A7<>"",Q7-P7,"") | S7: =IF(AND(A7<>"",Q7<>0),R7/Q7*100,"") | V7: 1.5 Cerrada | W7: 9
B8: =IF(A8<>"",IFERROR(VLOOKUP(A8,Agenda!A:E,5,0),"—"),"") | C8: =IF(A8<>"",IFERROR(VLOOKUP(A8,Agenda!A:K,11,0),"—"),"") | E8: =IF(A8<>"",IF(C8="Pick Up",7,IF(C8="1.5 Cerrada",9,IF(C8="2.5",10,IF(C8="3.5",12,0)))),"") | F8: =IF(AND(D8<>"",E8<>""),D8*E8,"") | P8: =IF(A8<>"",IFERROR(F8+G8+H8+I8+J8+K8+L8+M8+N8+O8,0),"") | Q8: =IF(A8<>"",IFERROR(VLOOKUP(A8,Agenda!A:N,14,0),0),"") | R8: =IF(A8<>"",Q8-P8,"") | S8: =IF(AND(A8<>"",Q8<>0),R8/Q8*100,"") | V8: 2.5 | W8: 10
B9: =IF(A9<>"",IFERROR(VLOOKUP(A9,Agenda!A:E,5,0),"—"),"") | C9: =IF(A9<>"",IFERROR(VLOOKUP(A9,Agenda!A:K,11,0),"—"),"") | E9: =IF(A9<>"",IF(C9="Pick Up",7,IF(C9="1.5 Cerrada",9,IF(C9="2.5",10,IF(C9="3.5",12,0)))),"") | F9: =IF(AND(D9<>"",E9<>""),D9*E9,"") | P9: =IF(A9<>"",IFERROR(F9+G9+H9+I9+J9+K9+L9+M9+N9+O9,0),"") | Q9: =IF(A9<>"",IFERROR(VLOOKUP(A9,Agenda!A:N,14,0),0),"") | R9: =IF(A9<>"",Q9-P9,"") | S9: =IF(AND(A9<>"",Q9<>0),R9/Q9*100,"") | V9: 3.5 | W9: 12
B10: =IF(A10<>"",IFERROR(VLOOKUP(A10,Agenda!A:E,5,0),"—"),"") | C10: =IF(A10<>"",IFERROR(VLOOKUP(A10,Agenda!A:K,11,0),"—"),"") | E10: =IF(A10<>"",IF(C10="Pick Up",7,IF(C10="1.5 Cerrada",9,IF(C10="2.5",10,IF(C10="3.5",12,0)))),"") | F10: =IF(AND(D10<>"",E10<>""),D10*E10,"") | P10: =IF(A10<>"",IFERROR(F10+G10+H10+I10+J10+K10+L10+M10+N10+O10,0),"") | Q10: =IF(A10<>"",IFERROR(VLOOKUP(A10,Agenda!A:N,14,0),0),"") | R10: =IF(A10<>"",Q10-P10,"") | S10: =IF(AND(A10<>"",Q10<>0),R10/Q10*100,"")
B11: =IF(A11<>"",IFERROR(VLOOKUP(A11,Agenda!A:E,5,0),"—"),"") | C11: =IF(A11<>"",IFERROR(VLOOKUP(A11,Agenda!A:K,11,0),"—"),"") | E11: =IF(A11<>"",IF(C11="Pick Up",7,IF(C11="1.5 Cerrada",9,IF(C11="2.5",10,IF(C11="3.5",12,0)))),"") | F11: =IF(AND(D11<>"",E11<>""),D11*E11,"") | P11: =IF(A11<>"",IFERROR(F11+G11+H11+I11+J11+K11+L11+M11+N11+O11,0),"") | Q11: =IF(A11<>"",IFERROR(VLOOKUP(A11,Agenda!A:N,14,0),0),"") | R11: =IF(A11<>"",Q11-P11,"") | S11: =IF(AND(A11<>"",Q11<>0),R11/Q11*100,"")
B12: =IF(A12<>"",IFERROR(VLOOKUP(A12,Agenda!A:E,5,0),"—"),"") | C12: =IF(A12<>"",IFERROR(VLOOKUP(A12,Agenda!A:K,11,0),"—"),"") | E12: =IF(A12<>"",IF(C12="Pick Up",7,IF(C12="1.5 Cerrada",9,IF(C12="2.5",10,IF(C12="3.5",12,0)))),"") | F12: =IF(AND(D12<>"",E12<>""),D12*E12,"") | P12: =IF(A12<>"",IFERROR(F12+G12+H12+I12+J12+K12+L12+M12+N12+O12,0),"") | Q12: =IF(A12<>"",IFERROR(VLOOKUP(A12,Agenda!A:N,14,0),0),"") | R12: =IF(A12<>"",Q12-P12,"") | S12: =IF(AND(A12<>"",Q12<>0),R12/Q12*100,"")
B13: =IF(A13<>"",IFERROR(VLOOKUP(A13,Agenda!A:E,5,0),"—"),"") | C13: =IF(A13<>"",IFERROR(VLOOKUP(A13,Agenda!A:K,11,0),"—"),"") | E13: =IF(A13<>"",IF(C13="Pick Up",7,IF(C13="1.5 Cerrada",9,IF(C13="2.5",10,IF(C13="3.5",12,0)))),"") | F13: =IF(AND(D13<>"",E13<>""),D13*E13,"") | P13: =IF(A13<>"",IFERROR(F13+G13+H13+I13+J13+K13+L13+M13+N13+O13,0),"") | Q13: =IF(A13<>"",IFERROR(VLOOKUP(A13,Agenda!A:N,14,0),0),"") | R13: =IF(A13<>"",Q13-P13,"") | S13: =IF(AND(A13<>"",Q13<>0),R13/Q13*100,"")
B14: =IF(A14<>"",IFERROR(VLOOKUP(A14,Agenda!A:E,5,0),"—"),"") | C14: =IF(A14<>"",IFERROR(VLOOKUP(A14,Agenda!A:K,11,0),"—"),"") | E14: =IF(A14<>"",IF(C14="Pick Up",7,IF(C14="1.5 Cerrada",9,IF(C14="2.5",10,IF(C14="3.5",12,0)))),"") | F14: =IF(AND(D14<>"",E14<>""),D14*E14,"") | P14: =IF(A14<>"",IFERROR(F14+G14+H14+I14+J14+K14+L14+M14+N14+O14,0),"") | Q14: =IF(A14<>"",IFERROR(VLOOKUP(A14,Agenda!A:N,14,0),0),"") | R14: =IF(A14<>"",Q14-P14,"") | S14: =IF(AND(A14<>"",Q14<>0),R14/Q14*100,"")
B15: =IF(A15<>"",IFERROR(VLOOKUP(A15,Agenda!A:E,5,0),"—"),"") | C15: =IF(A15<>"",IFERROR(VLOOKUP(A15,Agenda!A:K,11,0),"—"),"") | E15: =IF(A15<>"",IF(C15="Pick Up",7,IF(C15="1.5 Cerrada",9,IF(C15="2.5",10,IF(C15="3.5",12,0)))),"") | F15: =IF(AND(D15<>"",E15<>""),D15*E15,"") | P15: =IF(A15<>"",IFERROR(F15+G15+H15+I15+J15+K15+L15+M15+N15+O15,0),"") | Q15: =IF(A15<>"",IFERROR(VLOOKUP(A15,Agenda!A:N,14,0),0),"") | R15: =IF(A15<>"",Q15-P15,"") | S15: =IF(AND(A15<>"",Q15<>0),R15/Q15*100,"")
B16: =IF(A16<>"",IFERROR(VLOOKUP(A16,Agenda!A:E,5,0),"—"),"") | C16: =IF(A16<>"",IFERROR(VLOOKUP(A16,Agenda!A:K,11,0),"—"),"") | E16: =IF(A16<>"",IF(C16="Pick Up",7,IF(C16="1.5 Cerrada",9,IF(C16="2.5",10,IF(C16="3.5",12,0)))),"") | F16: =IF(AND(D16<>"",E16<>""),D16*E16,"") | P16: =IF(A16<>"",IFERROR(F16+G16+H16+I16+J16+K16+L16+M16+N16+O16,0),"") | Q16: =IF(A16<>"",IFERROR(VLOOKUP(A16,Agenda!A:N,14,0),0),"") | R16: =IF(A16<>"",Q16-P16,"") | S16: =IF(AND(A16<>"",Q16<>0),R16/Q16*100,"")
B17: =IF(A17<>"",IFERROR(VLOOKUP(A17,Agenda!A:E,5,0),"—"),"") | C17: =IF(A17<>"",IFERROR(VLOOKUP(A17,Agenda!A:K,11,0),"—"),"") | E17: =IF(A17<>"",IF(C17="Pick Up",7,IF(C17="1.5 Cerrada",9,IF(C17="2.5",10,IF(C17="3.5",12,0)))),"") | F17: =IF(AND(D17<>"",E17<>""),D17*E17,"") | P17: =IF(A17<>"",IFERROR(F17+G17+H17+I17+J17+K17+L17+M17+N17+O17,0),"") | Q17: =IF(A17<>"",IFERROR(VLOOKUP(A17,Agenda!A:N,14,0),0),"") | R17: =IF(A17<>"",Q17-P17,"") | S17: =IF(AND(A17<>"",Q17<>0),R17/Q17*100,"")
B18: =IF(A18<>"",IFERROR(VLOOKUP(A18,Agenda!A:E,5,0),"—"),"") | C18: =IF(A18<>"",IFERROR(VLOOKUP(A18,Agenda!A:K,11,0),"—"),"") | E18: =IF(A18<>"",IF(C18="Pick Up",7,IF(C18="1.5 Cerrada",9,IF(C18="2.5",10,IF(C18="3.5",12,0)))),"") | F18: =IF(AND(D18<>"",E18<>""),D18*E18,"") | P18: =IF(A18<>"",IFERROR(F18+G18+H18+I18+J18+K18+L18+M18+N18+O18,0),"") | Q18: =IF(A18<>"",IFERROR(VLOOKUP(A18,Agenda!A:N,14,0),0),"") | R18: =IF(A18<>"",Q18-P18,"") | S18: =IF(AND(A18<>"",Q18<>0),R18/Q18*100,"")
B19: =IF(A19<>"",IFERROR(VLOOKUP(A19,Agenda!A:E,5,0),"—"),"") | C19: =IF(A19<>"",IFERROR(VLOOKUP(A19,Agenda!A:K,11,0),"—"),"") | E19: =IF(A19<>"",IF(C19="Pick Up",7,IF(C19="1.5 Cerrada",9,IF(C19="2.5",10,IF(C19="3.5",12,0)))),"") | F19: =IF(AND(D19<>"",E19<>""),D19*E19,"") | P19: =IF(A19<>"",IFERROR(F19+G19+H19+I19+J19+K19+L19+M19+N19+O19,0),"") | Q19: =IF(A19<>"",IFERROR(VLOOKUP(A19,Agenda!A:N,14,0),0),"") | R19: =IF(A19<>"",Q19-P19,"") | S19: =IF(AND(A19<>"",Q19<>0),R19/Q19*100,"")
B20: =IF(A20<>"",IFERROR(VLOOKUP(A20,Agenda!A:E,5,0),"—"),"") | C20: =IF(A20<>"",IFERROR(VLOOKUP(A20,Agenda!A:K,11,0),"—"),"") | E20: =IF(A20<>"",IF(C20="Pick Up",7,IF(C20="1.5 Cerrada",9,IF(C20="2.5",10,IF(C20="3.5",12,0)))),"") | F20: =IF(AND(D20<>"",E20<>""),D20*E20,"") | P20: =IF(A20<>"",IFERROR(F20+G20+H20+I20+J20+K20+L20+M20+N20+O20,0),"") | Q20: =IF(A20<>"",IFERROR(VLOOKUP(A20,Agenda!A:N,14,0),0),"") | R20: =IF(A20<>"",Q20-P20,"") | S20: =IF(AND(A20<>"",Q20<>0),R20/Q20*100,"")
B21: =IF(A21<>"",IFERROR(VLOOKUP(A21,Agenda!A:E,5,0),"—"),"") | C21: =IF(A21<>"",IFERROR(VLOOKUP(A21,Agenda!A:K,11,0),"—"),"") | E21: =IF(A21<>"",IF(C21="Pick Up",7,IF(C21="1.5 Cerrada",9,IF(C21="2.5",10,IF(C21="3.5",12,0)))),"") | F21: =IF(AND(D21<>"",E21<>""),D21*E21,"") | P21: =IF(A21<>"",IFERROR(F21+G21+H21+I21+J21+K21+L21+M21+N21+O21,0),"") | Q21: =IF(A21<>"",IFERROR(VLOOKUP(A21,Agenda!A:N,14,0),0),"") | R21: =IF(A21<>"",Q21-P21,"") | S21: =IF(AND(A21<>"",Q21<>0),R21/Q21*100,"")
... B203: =IF(A203<>"",IFERROR(VLOOKUP(A203,Agenda!A:E,5,0),"—"),"") | C203: =IF(A203<>"",IFERROR(VLOOKUP(A203,Agenda!A:K,11,0),"—"),"") | E203: =IF(A203<>"",IF(C203="Pick Up",7,IF(C203="1.5 Cerrada",9,IF(C203="2.5",10,IF(C203="3.5",12,0)))),"") | F203: =IF(AND(D203<>"",E203<>""),D203*E203,"") | P203: =IF(A203<>"",IFERROR(F203+G203+H203+I203+J203+K203+L203+M203+N203+O203,0),"") | Q203: =IF(A203<>"",IFERROR(VLOOKUP(A203,Agenda!A:N,14,0),0),"") | R203: =IF(A203<>"",Q203-P203,"") | S203: =IF(AND(A203<>"",Q203<>0),R203/Q203*100,"")

Sheet Unidades
A1: MUDANZAS METEPEC — CONTROL POR UNIDAD
A2: Desempeño · Metas · Ocupación · Rentabilidad
A3: RESUMEN MENSUAL
A4: UNIDAD | B4: SERVICIOS | C4: VENTAS $ | D4: COSTOS $ | E4: UTILIDAD $ | F4: KM TOTAL | G4: META MES $ | H4: CUMP. % | I4: ESTADO
A5: Pick Up | B5: =COUNTIF(Agenda!K:K,"Pick Up") | C5: =SUMIF(Agenda!K:K,"Pick Up",Agenda!N:N) | D5: =SUMIF(Costos!C:C,"Pick Up",Costos!P:P) | E5: =C5-D5 | F5: =SUMIF(Costos!C:C,"Pick Up",Costos!D:D) | G5: 24250 | H5: =IF(G5>0,C5/G5*100,0) | I5: =IF(H5>=100,"✅ META CUMPLIDA",IF(H5>=70,"⚠️ En camino","🔴 Atención"))
A6: 1.5 Cerrada | B6: =COUNTIF(Agenda!K:K,"1.5 Cerrada") | C6: =SUMIF(Agenda!K:K,"1.5 Cerrada",Agenda!N:N) | D6: =SUMIF(Costos!C:C,"1.5 Cerrada",Costos!P:P) | E6: =C6-D6 | F6: =SUMIF(Costos!C:C,"1.5 Cerrada",Costos!D:D) | G6: 28450 | H6: =IF(G6>0,C6/G6*100,0) | I6: =IF(H6>=100,"✅ META CUMPLIDA",IF(H6>=70,"⚠️ En camino","🔴 Atención"))
A7: 2.5 | B7: =COUNTIF(Agenda!K:K,"2.5") | C7: =SUMIF(Agenda!K:K,"2.5",Agenda!N:N) | D7: =SUMIF(Costos!C:C,"2.5",Costos!P:P) | E7: =C7-D7 | F7: =SUMIF(Costos!C:C,"2.5",Costos!D:D) | G7: 31250 | H7: =IF(G7>0,C7/G7*100,0) | I7: =IF(H7>=100,"✅ META CUMPLIDA",IF(H7>=70,"⚠️ En camino","🔴 Atención"))
A8: 3.5 | B8: =COUNTIF(Agenda!K:K,"3.5") | C8: =SUMIF(Agenda!K:K,"3.5",Agenda!N:N) | D8: =SUMIF(Costos!C:C,"3.5",Costos!P:P) | E8: =C8-D8 | F8: =SUMIF(Costos!C:C,"3.5",Costos!D:D) | G8: 15250 | H8: =IF(G8>0,C8/G8*100,0) | I8: =IF(H8>=100,"✅ META CUMPLIDA",IF(H8>=70,"⚠️ En camino","🔴 Atención"))
A9: TOTAL FLOTA | B9: =SUM(B5:B8) | C9: =SUM(C5:C8) | D9: =SUM(D5:D8) | E9: =SUM(E5:E8) | F9: =SUM(F5:F8) | G9: =SUM(G5:G8)
A11: RESUMEN SEMANAL
A12: UNIDAD | B12: SERVICIOS SEMANA | C12: VENTAS SEMANA $ | D12: META SEMANA $ | E12: CUMP. SEMANAL % | F12: FALTA $ | G12: PROM. x SERVICIO $ | H12: MEJOR SEMANA | I12: NOTA
A13: Pick Up | B13: =COUNTIFS(Agenda!K:K,"Pick Up",Agenda!C:C,">="&TODAY()-7,Agenda!C:C,"<="&TODAY()) | C13: =SUMIFS(Agenda!N:N,Agenda!K:K,"Pick Up",Agenda!C:C,">="&TODAY()-7,Agenda!C:C,"<="&TODAY()) | D13: 5600 | E13: =IF(D13>0,C13/D13*100,0) | F13: =MAX(0,D13-C13) | G13: =IF(B13>0,C13/B13,0)
A14: 1.5 Cerrada | B14: =COUNTIFS(Agenda!K:K,"1.5 Cerrada",Agenda!C:C,">="&TODAY()-7,Agenda!C:C,"<="&TODAY()) | C14: =SUMIFS(Agenda!N:N,Agenda!K:K,"1.5 Cerrada",Agenda!C:C,">="&TODAY()-7,Agenda!C:C,"<="&TODAY()) | D14: 6570 | E14: =IF(D14>0,C14/D14*100,0) | F14: =MAX(0,D14-C14) | G14: =IF(B14>0,C14/B14,0)
A15: 2.5 | B15: =COUNTIFS(Agenda!K:K,"2.5",Agenda!C:C,">="&TODAY()-7,Agenda!C:C,"<="&TODAY()) | C15: =SUMIFS(Agenda!N:N,Agenda!K:K,"2.5",Agenda!C:C,">="&TODAY()-7,Agenda!C:C,"<="&TODAY()) | D15: 7220 | E15: =IF(D15>0,C15/D15*100,0) | F15: =MAX(0,D15-C15) | G15: =IF(B15>0,C15/B15,0)
A16: 3.5 | B16: =COUNTIFS(Agenda!K:K,"3.5",Agenda!C:C,">="&TODAY()-7,Agenda!C:C,"<="&TODAY()) | C16: =SUMIFS(Agenda!N:N,Agenda!K:K,"3.5",Agenda!C:C,">="&TODAY()-7,Agenda!C:C,"<="&TODAY()) | D16: 3520 | E16: =IF(D16>0,C16/D16*100,0) | F16: =MAX(0,D16-C16) | G16: =IF(B16>0,C16/B16,0)
A18: EXPEDIENTE TÉCNICO DE UNIDADES
A19: Datos técnicos · Documentación · Kilometraje · Alertas
A20: CAMPO | B20: Pick Up | C20: 1.5 Cerrada | D20: 2.5 | E20: 3.5 | F20: ALERTA
A21: Fecha de compra
A22: Valor de compra $
A23: Kilometraje inicial
A24: Kilometraje actual
A25: KM recorridos | B25: =IF(AND(B23<>"",B24<>""),B24-B23,"") | C25: =IF(AND(C23<>"",C24<>""),C24-C23,"") | D25: =IF(AND(D23<>"",D24<>""),D24-D23,"") | E25: =IF(AND(E23<>"",E24<>""),E24-E23,"")
A26: Vida útil objetivo | B26: 300000 | C26: 300000 | D26: 300000 | E26: 300000
A27: % vida útil consumida | B27: =IF(B25<>"",IFERROR(B25/B26*100,0),"") | C27: =IF(C25<>"",IFERROR(C25/C26*100,0),"") | D27: =IF(D25<>"",IFERROR(D25/D26*100,0),"") | E27: =IF(E25<>"",IFERROR(E25/E26*100,0),"") | F27: =IF(MAX(B27:E27)>=90,"🔴 CAMBIAR",IF(MAX(B27:E27)>=70,"⚠️ Revisar","✅ OK"))
A28: KM restantes | B28: =IF(B25<>"",IFERROR(B26-B25,0),"") | C28: =IF(C25<>"",IFERROR(C26-C25,0),"") | D28: =IF(D25<>"",IFERROR(D26-D25,0),"") | E28: =IF(E25<>"",IFERROR(E26-E25,0),"")
A29: Fecha próximo servicio
A30: KM para próx. servicio
A31: Próx. cambio de llantas
A32: Vencimiento seguro | F32: =IF(MIN(IF(B32:E32<>"",B32:E32,99999))-TODAY()<=30,"🔴 Vence pronto","✅ OK")
A33: Próxima verificación | F33: =IF(MIN(IF(B33:E33<>"",B33:E33,99999))-TODAY()<=30,"🔴 Vence pronto","✅ OK")
A34: Vencimiento tenencia | F34: =IF(MIN(IF(B34:E34<>"",B34:E34,99999))-TODAY()<=30,"🔴 Vence pronto","✅ OK")
A35: GPS instalado
A36: Observaciones unidad
A38: INDICADORES POR UNIDAD (Acumulado)
A39: INDICADOR | B39: Pick Up | C39: 1.5 Cerrada | D39: 2.5 | E39: 3.5
A40: Ventas acumuladas | B40: =SUMIF(Agenda!K:K,"Pick Up",Agenda!N:N) | C40: =SUMIF(Agenda!K:K,"1.5 Cerrada",Agenda!N:N) | D40: =SUMIF(Agenda!K:K,"2.5",Agenda!N:N) | E40: =SUMIF(Agenda!K:K,"3.5",Agenda!N:N)
A41: Costos acumulados | B41: =SUMIF(Costos!C:C,"Pick Up",Costos!P:P) | C41: =SUMIF(Costos!C:C,"1.5 Cerrada",Costos!P:P) | D41: =SUMIF(Costos!C:C,"2.5",Costos!P:P) | E41: =SUMIF(Costos!C:C,"3.5",Costos!P:P)
A42: Utilidad acumulada | B42: =SUMIF(Agenda!K:K,"Pick Up",Agenda!N:N)-SUMIF(Costos!C:C,"Pick Up",Costos!P:P) | C42: =SUMIF(Agenda!K:K,"1.5 Cerrada",Agenda!N:N)-SUMIF(Costos!C:C,"1.5 Cerrada",Costos!P:P) | D42: =SUMIF(Agenda!K:K,"2.5",Agenda!N:N)-SUMIF(Costos!C:C,"2.5",Costos!P:P) | E42: =SUMIF(Agenda!K:K,"3.5",Agenda!N:N)-SUMIF(Costos!C:C,"3.5",Costos!P:P)
A43: Servicios realizados | B43: =COUNTIF(Agenda!K:K,"Pick Up") | C43: =COUNTIF(Agenda!K:K,"1.5 Cerrada") | D43: =COUNTIF(Agenda!K:K,"2.5") | E43: =COUNTIF(Agenda!K:K,"3.5")
...

Sheet Flujo
A1: MUDANZAS METEPEC — FLUJO DE EFECTIVO
A2: Cada movimiento de dinero: entradas · salidas · saldo acumulado
A3: FECHA | B3: CONCEPTO | C3: ENTRADA $ | D3: SALIDA $ | E3: CATEGORÍA | F3: UNIDAD | G3: FOLIO | H3: MÉTODO PAGO | I3: SALDO ACUM. $
B4: SALDO INICIAL | I4: =IF(C4<>"",C4,0)
I5: =IF(OR(C5<>"",D5<>""),I4+IF(C5<>"",C5,0)-IF(D5<>"",D5,0),"")
I6: =IF(OR(C6<>"",D6<>""),I5+IF(C6<>"",C6,0)-IF(D6<>"",D6,0),"")
I7: =IF(OR(C7<>"",D7<>""),I6+IF(C7<>"",C7,0)-IF(D7<>"",D7,0),"")
I8: =IF(OR(C8<>"",D8<>""),I7+IF(C8<>"",C8,0)-IF(D8<>"",D8,0),"")
I9: =IF(OR(C9<>"",D9<>""),I8+IF(C9<>"",C9,0)-IF(D9<>"",D9,0),"")
I10: =IF(OR(C10<>"",D10<>""),I9+IF(C10<>"",C10,0)-IF(D10<>"",D10,0),"")
I11: =IF(OR(C11<>"",D11<>""),I10+IF(C11<>"",C11,0)-IF(D11<>"",D11,0),"") | K11: RESUMEN FLUJO
I12: =IF(OR(C12<>"",D12<>""),I11+IF(C12<>"",C12,0)-IF(D12<>"",D12,0),"") | K12: Total Entradas | L12: =IFERROR(SUM(C4:C504),0)
I13: =IF(OR(C13<>"",D13<>""),I12+IF(C13<>"",C13,0)-IF(D13<>"",D13,0),"") | K13: Total Salidas | L13: =IFERROR(SUM(D4:D504),0)
I14: =IF(OR(C14<>"",D14<>""),I13+IF(C14<>"",C14,0)-IF(D14<>"",D14,0),"") | K14: Saldo Neto | L14: =K12-K13
I15: =IF(OR(C15<>"",D15<>""),I14+IF(C15<>"",C15,0)-IF(D15<>"",D15,0),"")
I16: =IF(OR(C16<>"",D16<>""),I15+IF(C16<>"",C16,0)-IF(D16<>"",D16,0),"") | K16: Por categoría:
I17: =IF(OR(C17<>"",D17<>""),I16+IF(C17<>"",C17,0)-IF(D17<>"",D17,0),"") | K17: Servicios | L17: =SUMIF(E4:E504,"Servicio",C4:C504)
I18: =IF(OR(C18<>"",D18<>""),I17+IF(C18<>"",C18,0)-IF(D18<>"",D18,0),"") | K18: G. Operativo | L18: =SUMIF(E4:E504,"Gasto operativo",D4:D504)
I19: =IF(OR(C19<>"",D19<>""),I18+IF(C19<>"",C19,0)-IF(D19<>"",D19,0),"") | K19: Nómina | L19: =SUMIF(E4:E504,"Nómina",D4:D504)
I20: =IF(OR(C20<>"",D20<>""),I19+IF(C20<>"",C20,0)-IF(D20<>"",D20,0),"") | K20: Publicidad | L20: =SUMIF(E4:E504,"Publicidad",D4:D504)
I21: =IF(OR(C21<>"",D21<>""),I20+IF(C21<>"",C21,0)-IF(D21<>"",D21,0),"") | K21: Mantenimiento | L21: =SUMIF(E4:E504,"Mantenimiento",D4:D504)
I22: =IF(OR(C22<>"",D22<>""),I21+IF(C22<>"",C22,0)-IF(D22<>"",D22,0),"")
I23: =IF(OR(C23<>"",D23<>""),I22+IF(C23<>"",C23,0)-IF(D23<>"",D23,0),"")
I24: =IF(OR(C24<>"",D24<>""),I23+IF(C24<>"",C24,0)-IF(D24<>"",D24,0),"")
I25: =IF(OR(C25<>"",D25<>""),I24+IF(C25<>"",C25,0)-IF(D25<>"",D25,0),"")
I26: =IF(OR(C26<>"",D26<>""),I25+IF(C26<>"",C26,0)-IF(D26<>"",D26,0),"")
I27: =IF(OR(C27<>"",D27<>""),I26+IF(C27<>"",C27,0)-IF(D27<>"",D27,0),"")
I28: =IF(OR(C28<>"",D28<>""),I27+IF(C28<>"",C28,0)-IF(D28<>"",D28,0),"")
I29: =IF(OR(C29<>"",D29<>""),I28+IF(C29<>"",C29,0)-IF(D29<>"",D29,0),"")
I30: =IF(OR(C30<>"",D30<>""),I29+IF(C30<>"",C30,0)-IF(D30<>"",D30,0),"")
I31: =IF(OR(C31<>"",D31<>""),I30+IF(C31<>"",C31,0)-IF(D31<>"",D31,0),"")
I32: =IF(OR(C32<>"",D32<>""),I31+IF(C32<>"",C32,0)-IF(D32<>"",D32,0),"")
I33: =IF(OR(C33<>"",D33<>""),I32+IF(C33<>"",C33,0)-IF(D33<>"",D33,0),"")
... I504: =IF(OR(C504<>"",D504<>""),I503+IF(C504<>"",C504,0)-IF(D504<>"",D504,0),"")

Sheet Gastos Fijos
A1: MUDANZAS METEPEC — GASTOS FIJOS
A2: Gastos fijos mensuales · Punto de equilibrio · Avance de cobertura
A3: CONCEPTO | B3: MONTO MES $ | C3: MONTO SEM $ | D3: % DEL TOTAL | E3: CATEGORÍA
A4: Camioneta 2.5 | B4: 16000 | C4: =B4/4.33 | D4: =B4/$B$11*100 | E4: Unidad
A5: Camioneta 1.5 C | B5: 13200 | C5: =B5/4.33 | D5: =B5/$B$11*100 | E5: Unidad
A6: Camioneta Pick Up | B6: 9000 | C6: =B6/4.33 | D6: =B6/$B$11*100 | E6: Unidad
A7: Pensión (estacionam) | B7: 20000 | C7: =B7/4.33 | D7: =B7/$B$11*100 | E7: Operativo
A8: Anuncios / Publicidad | B8: 6000 | C8: =B8/4.33 | D8: =B8/$B$11*100 | E8: Marketing
A9: Suscripciones | B9: 5000 | C9: =B9/4.33 | D9: =B9/$B$11*100 | E9: Admin
A10: Administración | B10: 30000 | C10: =B10/4.33 | D10: =B10/$B$11*100 | E10: Admin
A11: TOTAL MENSUAL | B11: =SUM(B4:B10) | C11: =B11/4.33 | D11: 100%
A13: AVANCE DE COBERTURA DE GASTOS FIJOS
A14: Ventas del mes (total flota) | B14: =IFERROR(SUM(Agenda!N:N),0)
A15: Gastos fijos totales | B15: =B11
A16: Gastos fijos CUBIERTOS | B16: =MIN(B14,B15)
A17: FALTA para cubrir gastos fijos | B17: =MAX(0,B15-B14)
A18: % Cobertura alcanzado | B18: =IF(B15>0,B14/B15*100,0)
A19: Ventas necesarias p/equilibrio | B19: =B15
A20: Margen sobre gastos fijos | B20: =MAX(0,B14-B15)
A22: DISTRIBUCIÓN META POR UNIDAD (vs. Gastos Fijos)
A23: UNIDAD | B23: META MES $ | C23: META SEM $ | D23: % META/GASTO | E23: VENTAS REALES $
A24: Pick Up | B24: 24250 | C24: 5600 | D24: =B24/$B$11*100 | E24: =SUMIF(Agenda!K:K,"Pick Up",Agenda!N:N)
A25: 1.5 Cerrada | B25: 28450 | C25: 6570 | D25: =B25/$B$11*100 | E25: =SUMIF(Agenda!K:K,"1.5 Cerrada",Agenda!N:N)
A26: 2.5 | B26: 31250 | C26: 7220 | D26: =B26/$B$11*100 | E26: =SUMIF(Agenda!K:K,"2.5",Agenda!N:N)
A27: 3.5 | B27: 15250 | C27: 3520 | D27: =B27/$B$11*100 | E27: =SUMIF(Agenda!K:K,"3.5",Agenda!N:N)

Sheet Clientes
A1: MUDANZAS METEPEC — CLIENTES Y SEGUIMIENTO
A2: CRM básico: contacto → cotización → cierre → reseña → recurrencia
A3: NOMBRE | B3: TELÉFONO | C3: F.CONTACTO | D3: FUENTE | E3: SERVICIO SOL. | F3: COTIZACIÓN $ | G3: CERRÓ | H3: MOTIVO NO CERRÓ | I3: F.SEGUIMIENTO | J3: RESEÑA SOL. | K3: RESEÑA REC. | L3: RECURRENTE | M3: VALOR CLIENTE $ | N3: SERVICIOS TOTAL | O3: ÚLTIMO SERVICIO | P3: OBSERVACIONES | R3: MÉTRICAS CRM
M4: =IF(A4<>"",IFERROR(SUMIF(Agenda!E:E,A4,Agenda!N:N),0),"") | N4: =IF(A4<>"",IFERROR(COUNTIF(Agenda!E:E,A4),0),"") | O4: =IF(A4<>"",IFERROR(MAXIFS(Agenda!C:C,Agenda!E:E,A4),""),"") | R4: Total contactos | S4: =COUNTA(A4:A303)
M5: =IF(A5<>"",IFERROR(SUMIF(Agenda!E:E,A5,Agenda!N:N),0),"") | N5: =IF(A5<>"",IFERROR(COUNTIF(Agenda!E:E,A5),0),"") | O5: =IF(A5<>"",IFERROR(MAXIFS(Agenda!C:C,Agenda!E:E,A5),""),"") | R5: Total cerrados | S5: =COUNTIF(G4:G303,"Sí")
M6: =IF(A6<>"",IFERROR(SUMIF(Agenda!E:E,A6,Agenda!N:N),0),"") | N6: =IF(A6<>"",IFERROR(COUNTIF(Agenda!E:E,A6),0),"") | O6: =IF(A6<>"",IFERROR(MAXIFS(Agenda!C:C,Agenda!E:E,A6),""),"") | R6: No cerrados | S6: =COUNTIF(G4:G303,"No")
M7: =IF(A7<>"",IFERROR(SUMIF(Agenda!E:E,A7,Agenda!N:N),0),"") | N7: =IF(A7<>"",IFERROR(COUNTIF(Agenda!E:E,A7),0),"") | O7: =IF(A7<>"",IFERROR(MAXIFS(Agenda!C:C,Agenda!E:E,A7),""),"") | R7: Tasa de cierre % | S7: =IF(COUNTA(A4:A303)>0,COUNTIF(G4:G303,"Sí")/COUNTA(A4:A303)*100,0)
M8: =IF(A8<>"",IFERROR(SUMIF(Agenda!E:E,A8,Agenda!N:N),0),"") | N8: =IF(A8<>"",IFERROR(COUNTIF(Agenda!E:E,A8),0),"") | O8: =IF(A8<>"",IFERROR(MAXIFS(Agenda!C:C,Agenda!E:E,A8),""),"") | R8: Reseñas recibidas | S8: =COUNTIF(K4:K303,"Sí")
M9: =IF(A9<>"",IFERROR(SUMIF(Agenda!E:E,A9,Agenda!N:N),0),"") | N9: =IF(A9<>"",IFERROR(COUNTIF(Agenda!E:E,A9),0),"") | O9: =IF(A9<>"",IFERROR(MAXIFS(Agenda!C:C,Agenda!E:E,A9),""),"") | R9: Clientes recurrentes | S9: =COUNTIF(L4:L303,"Sí")
M10: =IF(A10<>"",IFERROR(SUMIF(Agenda!E:E,A10,Agenda!N:N),0),"") | N10: =IF(A10<>"",IFERROR(COUNTIF(Agenda!E:E,A10),0),"") | O10: =IF(A10<>"",IFERROR(MAXIFS(Agenda!C:C,Agenda!E:E,A10),""),"") | R10: Fuente: Facebook | S10: =COUNTIF(D4:D303,"Facebook")
M11: =IF(A11<>"",IFERROR(SUMIF(Agenda!E:E,A11,Agenda!N:N),0),"") | N11: =IF(A11<>"",IFERROR(COUNTIF(Agenda!E:E,A11),0),"") | O11: =IF(A11<>"",IFERROR(MAXIFS(Agenda!C:C,Agenda!E:E,A11),""),"") | R11: Fuente: WhatsApp | S11: =COUNTIF(D4:D303,"WhatsApp")
M12: =IF(A12<>"",IFERROR(SUMIF(Agenda!E:E,A12,Agenda!N:N),0),"") | N12: =IF(A12<>"",IFERROR(COUNTIF(Agenda!E:E,A12),0),"") | O12: =IF(A12<>"",IFERROR(MAXIFS(Agenda!C:C,Agenda!E:E,A12),""),"") | R12: Fuente: Recomendación | S12: =COUNTIF(D4:D303,"Recomendación")
M13: =IF(A13<>"",IFERROR(SUMIF(Agenda!E:E,A13,Agenda!N:N),0),"") | N13: =IF(A13<>"",IFERROR(COUNTIF(Agenda!E:E,A13),0),"") | O13: =IF(A13<>"",IFERROR(MAXIFS(Agenda!C:C,Agenda!E:E,A13),""),"") | R13: Fuente: Saleads | S13: =COUNTIF(D4:D303,"Saleads")
M14: =IF(A14<>"",IFERROR(SUMIF(Agenda!E:E,A14,Agenda!N:N),0),"") | N14: =IF(A14<>"",IFERROR(COUNTIF(Agenda!E:E,A14),0),"") | O14: =IF(A14<>"",IFERROR(MAXIFS(Agenda!C:C,Agenda!E:E,A14),""),"")
M15: =IF(A15<>"",IFERROR(SUMIF(Agenda!E:E,A15,Agenda!N:N),0),"") | N15: =IF(A15<>"",IFERROR(COUNTIF(Agenda!E:E,A15),0),"") | O15: =IF(A15<>"",IFERROR(MAXIFS(Agenda!C:C,Agenda!E:E,A15),""),"")
M16: =IF(A16<>"",IFERROR(SUMIF(Agenda!E:E,A16,Agenda!N:N),0),"") | N16: =IF(A16<>"",IFERROR(COUNTIF(Agenda!E:E,A16),0),"") | O16: =IF(A16<>"",IFERROR(MAXIFS(Agenda!C:C,Agenda!E:E,A16),""),"")
M17: =IF(A17<>"",IFERROR(SUMIF(Agenda!E:E,A17,Agenda!N:N),0),"") | N17: =IF(A17<>"",IFERROR(COUNTIF(Agenda!E:E,A17),0),"") | O17: =IF(A17<>"",IFERROR(MAXIFS(Agenda!C:C,Agenda!E:E,A17),""),"")
M18: =IF(A18<>"",IFERROR(SUMIF(Agenda!E:E,A18,Agenda!N:N),0),"") | N18: =IF(A18<>"",IFERROR(COUNTIF(Agenda!E:E,A18),0),"") | O18: =IF(A18<>"",IFERROR(MAXIFS(Agenda!C:C,Agenda!E:E,A18),""),"")
M19: =IF(A19<>"",IFERROR(SUMIF(Agenda!E:E,A19,Agenda!N:N),0),"") | N19: =IF(A19<>"",IFERROR(COUNTIF(Agenda!E:E,A19),0),"") | O19: =IF(A19<>"",IFERROR(MAXIFS(Agenda!C:C,Agenda!E:E,A19),""),"")
M20: =IF(A20<>"",IFERROR(SUMIF(Agenda!E:E,A20,Agenda!N:N),0),"") | N20: =IF(A20<>"",IFERROR(COUNTIF(Agenda!E:E,A20),0),"") | O20: =IF(A20<>"",IFERROR(MAXIFS(Agenda!C:C,Agenda!E:E,A20),""),"")
M21: =IF(A21<>"",IFERROR(SUMIF(Agenda!E:E,A21,Agenda!N:N),0),"") | N21: =IF(A21<>"",IFERROR(COUNTIF(Agenda!E:E,A21),0),"") | O21: =IF(A21<>"",IFERROR(MAXIFS(Agenda!C:C,Agenda!E:E,A21),""),"")
M22: =IF(A22<>"",IFERROR(SUMIF(Agenda!E:E,A22,Agenda!N:N),0),"") | N22: =IF(A22<>"",IFERROR(COUNTIF(Agenda!E:E,A22),0),"") | O22: =IF(A22<>"",IFERROR(MAXIFS(Agenda!C:C,Agenda!E:E,A22),""),"")
M23: =IF(A23<>"",IFERROR(SUMIF(Agenda!E:E,A23,Agenda!N:N),0),"") | N23: =IF(A23<>"",IFERROR(COUNTIF(Agenda!E:E,A23),0),"") | O23: =IF(A23<>"",IFERROR(MAXIFS(Agenda!C:C,Agenda!E:E,A23),""),"")
M24: =IF(A24<>"",IFERROR(SUMIF(Agenda!E:E,A24,Agenda!N:N),0),"") | N24: =IF(A24<>"",IFERROR(COUNTIF(Agenda!E:E,A24),0),"") | O24: =IF(A24<>"",IFERROR(MAXIFS(Agenda!C:C,Agenda!E:E,A24),""),"")
M25: =IF(A25<>"",IFERROR(SUMIF(Agenda!E:E,A25,Agenda!N:N),0),"") | N25: =IF(A25<>"",IFERROR(COUNTIF(Agenda!E:E,A25),0),"") | O25: =IF(A25<>"",IFERROR(MAXIFS(Agenda!C:C,Agenda!E:E,A25),""),"")
... M303: =IF(A303<>"",IFERROR(SUMIF(Agenda!E:E,A303,Agenda!N:N),0),"") | N303: =IF(A303<>"",IFERROR(COUNTIF(Agenda!E:E,A303),0),"") | O303: =IF(A303<>"",IFERROR(MAXIFS(Agenda!C:C,Agenda!E:E,A303),""),"")

Sheet Mantenimiento
A1: MUDANZAS METEPEC — HISTORIAL DE MANTENIMIENTO
A2: Registro completo por unidad · Conectado con Flujo de Efectivo
A3: FOLIO MTO | B3: FECHA | C3: UNIDAD | D3: TIPO | E3: KM EN MTO | F3: COSTO $ | G3: PROVEEDOR | H3: FOLIO GASTO | I3: OBSERVACIONES | K3: RESUMEN COSTOS MTO
A4: =IF(B4<>"","MTO-"&TEXT(ROW()-3,"000"),"") | K4: TOTAL FLOTA | L4: =SUM(F4:F303)
A5: =IF(B5<>"","MTO-"&TEXT(ROW()-3,"000"),"") | K5: Pick Up | L5: =SUMIF(C4:C303,"Pick Up",F4:F303)
A6: =IF(B6<>"","MTO-"&TEXT(ROW()-3,"000"),"") | K6: 1.5 Cerrada | L6: =SUMIF(C4:C303,"1.5 Cerrada",F4:F303)
A7: =IF(B7<>"","MTO-"&TEXT(ROW()-3,"000"),"") | K7: 2.5 | L7: =SUMIF(C4:C303,"2.5",F4:F303)
A8: =IF(B8<>"","MTO-"&TEXT(ROW()-3,"000"),"") | K8: 3.5 | L8: =SUMIF(C4:C303,"3.5",F4:F303)
A9: =IF(B9<>"","MTO-"&TEXT(ROW()-3,"000"),"")
A10: =IF(B10<>"","MTO-"&TEXT(ROW()-3,"000"),"") | K10: Cambio aceite | L10: =SUMIF(D4:D303,"Cambio aceite",F4:F303)
A11: =IF(B11<>"","MTO-"&TEXT(ROW()-3,"000"),"") | K11: Cambio llantas | L11: =SUMIF(D4:D303,"Cambio llantas",F4:F303)
A12: =IF(B12<>"","MTO-"&TEXT(ROW()-3,"000"),"") | K12: Frenos | L12: =SUMIF(D4:D303,"Frenos",F4:F303)
A13: =IF(B13<>"","MTO-"&TEXT(ROW()-3,"000"),"") | K13: Afinación | L13: =SUMIF(D4:D303,"Afinación",F4:F303)
A14: =IF(B14<>"","MTO-"&TEXT(ROW()-3,"000"),"") | K14: Motor | L14: =SUMIF(D4:D303,"Motor",F4:F303)
A15: =IF(B15<>"","MTO-"&TEXT(ROW()-3,"000"),"") | K15: Preventivo | L15: =SUMIF(D4:D303,"Preventivo",F4:F303)
A16: =IF(B16<>"","MTO-"&TEXT(ROW()-3,"000"),"")
A17: =IF(B17<>"","MTO-"&TEXT(ROW()-3,"000"),"") | K17: Nº registros | L17: =COUNTA(B4:B303)
A18: =IF(B18<>"","MTO-"&TEXT(ROW()-3,"000"),"") | K18: Últ. registro | L18: =IFERROR(MAX(B4:B303),"—")
A19: =IF(B19<>"","MTO-"&TEXT(ROW()-3,"000"),"") | K19: Prom. x evento $ | L19: =IFERROR(SUM(F4:F303)/COUNTA(B4:B303),0)
A20: =IF(B20<>"","MTO-"&TEXT(ROW()-3,"000"),"")
A21: =IF(B21<>"","MTO-"&TEXT(ROW()-3,"000"),"")
A22: =IF(B22<>"","MTO-"&TEXT(ROW()-3,"000"),"")
A23: =IF(B23<>"","MTO-"&TEXT(ROW()-3,"000"),"")
A24: =IF(B24<>"","MTO-"&TEXT(ROW()-3,"000"),"")
A25: =IF(B25<>"","MTO-"&TEXT(ROW()-3,"000"),"")
A26: =IF(B26<>"","MTO-"&TEXT(ROW()-3,"000"),"")
A27: =IF(B27<>"","MTO-"&TEXT(ROW()-3,"000"),"")
A28: =IF(B28<>"","MTO-"&TEXT(ROW()-3,"000"),"")
A29: =IF(B29<>"","MTO-"&TEXT(ROW()-3,"000"),"")
A30: =IF(B30<>"","MTO-"&TEXT(ROW()-3,"000"),"")
A31: =IF(B31<>"","MTO-"&TEXT(ROW()-3,"000"),"")
... A303: =IF(B303<>"","MTO-"&TEXT(ROW()-3,"000"),"")

Sheet Instrucciones
A1: MUDANZAS METEPEC — GUÍA DE USO DEL SISTEMA
B3: FLUJO DE TRABAJO DIARIO:
B4: 1. AGENDA → Registra cada servicio desde WhatsApp. El folio se genera solo.
B5: 2. AGENDA → Llena: cliente, fecha, hora, tipo, origen, destino, unidad, precio cotizado, anticipo.
B6: 3. AGENDA → Cambia el Estado conforme avanza: Pendiente → Confirmado → En proceso → Terminado.
B7: 4. AGENDA → Llena las columnas nuevas: Prioridad, Fuente, Tipo cliente, Horas, Fotos/Videos.
B8: 5. COSTOS → Copia el Folio de la Agenda. El cliente y la unidad se llenan solos.
B9: 6. COSTOS → Llena kilómetros reales, chofer, ayudantes, maniobras, casetas, comidas, etc.
B10: 7. FLUJO → Registra cada entrada de dinero (anticipo, saldo) y cada gasto del día.
B11: 8. MANTENIMIENTO → Cada vez que hagas mantenimiento a una unidad, regístralo aquí.
B12: 9. UNIDADES → Actualiza el Kilometraje actual de cada unidad al menos una vez por semana.
B13: 10. CLIENTES → Registra cada contacto nuevo. Llena si cerró, fuente y seguimiento.
B14: 11. DASHBOARD → Revisa cada mañana el estado del negocio en 30 segundos.
... B51: Todo lo que supere $99,200 en ventas es utilidad real del negocio.
